Workbook

Sheet 📋 Instruções
B2: PLANILHA DE RESULTADOS · 49 Educação
B3: Resultado mensal consolidado · 3 áreas de receita + Financeiro
B5: COMO FUNCIONA
B6: Cada líder preenche apenas a sua aba até o dia 15 do mês seguinte. A Luana consolida o Financeiro e o dashboard HTML lê a aba "📤 Export" automaticamente.
B8: ÁREAS E RESPONSÁVEIS
B9: Aba | D9: Responsável | F9: Prazo de Envio
B10: 🛠 Produto | D10: Tiago Toigo | F10: Até dia 15 do mês seguinte
B11: 🤝 Comercial B2B | D11: Marcelo Câmara | F11: Até dia 15 do mês seguinte
B12: 📋 Licitações | D12: Rafael Peck | F12: Até dia 15 do mês seguinte
B13: 💰 Financeiro | D13: Luana / Financeiro | F13: Após todas as áreas preencherem
B14: 📤 Export | D14: Automático (consolidação) | F14: Lido pelo One Page HTML
B17: LEGENDA DE CORES
C18: Campo de preenchimento | E18: Preencha o número conforme rótulo do indicador
B19: 1.000 | C19: Calculado automaticamente | E19: Não edite — fórmula puxa de outras células
B20: 1.000 | C20: Total / Cabeçalho de seção | E20: Linhas de subtotal e categorias
B23: ⚠ IMPORTANTE — VENDIDO vs RECEBIDO
B24: Os líderes preenchem o que foi VENDIDO no mês (contratos fechados). A Luana preenche o que foi RECEBIDO (entrada em caixa). O dashboard mostra o gap entre vendido e recebido por área.

Sheet 🛠 Produto
B2: 🛠 PRODUTO — Tiago Toigo
B3: Entrega das aulas/hot seats, saúde da base contratada, vendas de 49 Code e tech
B5: Indicador | C5: Jan | D5: Fev | E5: Mar | F5: Abr | G5: Mai | H5: Jun | I5: Jul | J5: Ago | K5: Set | L5: Out | M5: Nov | N5: Dez | O5: Total/Média
B6: ENTREGA
B7: Aulas / Hot Seats Realizadas | O7: =SUM(C7:N7)
B8: Marcos Entregues no Mês | O8: =SUM(C8:N8)
B9: SLA de Entrega (%) | O9: =IFERROR(AVERAGE(C9:N9),0)
B11: SAÚDE DA BASE
B12: Contratos Ativos | O12: =SUM(C12:N12)
B13: NPS | O13: =SUM(C13:N13)
B15: RECEITA (VENDIDA NO MÊS)
B16: Vendas de 49 Code (qtd) | O16: =SUM(C16:N16)
B17: Receita de 49 Code (R$) | O17: =SUM(C17:N17)
B18: Receita Total da Área (R$) | O18: =SUM(C18:N18)
B20: TECH
B21: Uptime das Plataformas (%) | O21: =IFERROR(AVERAGE(C21:N21),0)
B22: Bugs Críticos Reportados | O22: =SUM(C22:N22)
B23: Bugs Críticos Resolvidos | O23: =SUM(C23:N23)
B24: Features Lançadas no Mês | O24: =SUM(C24:N24)

Sheet 🤝 B2B
B2: 🤝 COMERCIAL B2B — Marcelo Câmara
B3: Captação de novos clientes B2B (Sebrae, SATC, PUC, etc), funil e fechamento
B5: Indicador | C5: Jan | D5: Fev | E5: Mar | F5: Abr | G5: Mai | H5: Jun | I5: Jul | J5: Ago | K5: Set | L5: Out | M5: Nov | N5: Dez | O5: Total/Média
B6: MARKETING / FUNIL
B7: Investimento ADS (R$) | O7: =SUM(C7:N7)
B8: Leads Gerados | O8: =SUM(C8:N8)
B9: MQLs | O9: =SUM(C9:N9)
B10: SQLs | O10: =SUM(C10:N10)
B11: CAC (auto) | C11: =IFERROR(C7/C17,0) | D11: =IFERROR(D7/D17,0) | E11: =IFERROR(E7/E17,0) | F11: =IFERROR(F7/F17,0) | G11: =IFERROR(G7/G17,0) | H11: =IFERROR(H7/H17,0) | I11: =IFERROR(I7/I17,0) | J11: =IFERROR(J7/J17,0) | ... N11: =IFERROR(N7/N17,0) | O11: =IFERROR(SUM(C7:N7)/SUM(C17:N17),0)
B13: PIPELINE & VENDAS
B14: Pipeline Ativo (R$) | O14: =SUM(C14:N14)
B15: Novos Leads B2B no Mês | O15: =SUM(C15:N15)
B16: Propostas Enviadas | O16: =SUM(C16:N16)
B17: Contratos Fechados (qtd) | O17: =SUM(C17:N17)
B18: Receita B2B Vendida (R$) | O18: =SUM(C18:N18)
B19: Ticket Médio B2B (auto) | C19: =IFERROR(C18/C17,0) | D19: =IFERROR(D18/D17,0) | E19: =IFERROR(E18/E17,0) | F19: =IFERROR(F18/F17,0) | G19: =IFERROR(G18/G17,0) | H19: =IFERROR(H18/H17,0) | I19: =IFERROR(I18/I17,0) | J19: =IFERROR(J18/J17,0) | ... N19: =IFERROR(N18/N17,0) | O19: =IFERROR(SUM(C18:N18)/SUM(C17:N17),0)
B20: Taxa de Fechamento (auto) | C20: =IFERROR(C17/C10,0) | D20: =IFERROR(D17/D10,0) | E20: =IFERROR(E17/E10,0) | F20: =IFERROR(F17/F10,0) | G20: =IFERROR(G17/G10,0) | H20: =IFERROR(H17/H10,0) | I20: =IFERROR(I17/I10,0) | J20: =IFERROR(J17/J10,0) | ... N20: =IFERROR(N17/N10,0) | O20: =IFERROR(AVERAGE(C20:N20),0)
B21: Ciclo Médio de Venda (dias) | O21: =IFERROR(AVERAGE(C21:N21),0)

Sheet 📋 Licitações
B2: 📋 LICITAÇÕES — Rafael Peck
B3: Receita via editais públicos · pipeline, prestação de contas e operacional
B5: Indicador | C5: Jan | D5: Fev | E5: Mar | F5: Abr | G5: Mai | H5: Jun | I5: Jul | J5: Ago | K5: Set | L5: Out | M5: Nov | N5: Dez | O5: Total/Média
B6: PIPELINE DE EDITAIS
B7: Editais Monitorados | O7: =SUM(C7:N7)
B8: Editais Submetidos no Mês | O8: =SUM(C8:N8)
B9: Editais Ganhos no Mês | O9: =SUM(C9:N9)
B10: Taxa de Êxito (auto) | C10: =IFERROR(C9/C8,0) | D10: =IFERROR(D9/D8,0) | E10: =IFERROR(E9/E8,0) | F10: =IFERROR(F9/F8,0) | G10: =IFERROR(G9/G8,0) | H10: =IFERROR(H9/H8,0) | I10: =IFERROR(I9/I8,0) | J10: =IFERROR(J9/J8,0) | ... N10: =IFERROR(N9/N8,0) | O10: =IFERROR(AVERAGE(C10:N10),0)
B12: RECEITA (VENDIDA NO MÊS)
B13: Receita de Editais Ganhos (R$) | O13: =SUM(C13:N13)
B14: Valor Total Pipeline de Editais (R$) | O14: =SUM(C14:N14)
B16: PRESTAÇÃO DE CONTAS
B17: Contratos Vigentes em Execução | O17: =SUM(C17:N17)
B18: Prestações de Contas Entregues | O18: =SUM(C18:N18)
B19: Prestações Pendentes | O19: =SUM(C19:N19)
B20: Prestações em Atraso | O20: =SUM(C20:N20)
B22: OPERACIONAL
B23: TRs em Aprovação | O23: =SUM(C23:N23)
B24: Follow-ups Agendados | O24: =SUM(C24:N24)

Sheet 💰 Financeiro
B2: 💰 FINANCEIRO — Luana / Financeiro
B3: Caixa, recebimentos efetivos, despesas e indicadores · preenchido após áreas
B5: Indicador | C5: Jan | D5: Fev | E5: Mar | F5: Abr | G5: Mai | H5: Jun | I5: Jul | J5: Ago | K5: Set | L5: Out | M5: Nov | N5: Dez | O5: Total/Média
B6: CAIXA & RECEBIMENTOS
B7: Saldo Inicial de Caixa (R$) | O7: =SUM(C7:N7)
B8: Recebimentos B2B (R$) | O8: =SUM(C8:N8)
B9: Recebimentos Produto/B2C (R$) | O9: =SUM(C9:N9)
B10: Recebimentos de Editais (R$) | O10: =SUM(C10:N10)
B11: Outras Receitas (R$) | O11: =SUM(C11:N11)
B12: Recebimentos Totais (auto) | C12: =SUM(C8:C11) | D12: =SUM(D8:D11) | E12: =SUM(E8:E11) | F12: =SUM(F8:F11) | G12: =SUM(G8:G11) | H12: =SUM(H8:H11) | I12: =SUM(I8:I11) | J12: =SUM(J8:J11) | ... N12: =SUM(N8:N11) | O12: =SUM(C12:N12)
B14: VENDIDO NO MÊS (consolidado das áreas)
B15: Vendido B2B (auto) | C15: ='🤝 B2B'!C18 | D15: ='🤝 B2B'!D18 | E15: ='🤝 B2B'!E18 | F15: ='🤝 B2B'!F18 | G15: ='🤝 B2B'!G18 | H15: ='🤝 B2B'!H18 | I15: ='🤝 B2B'!I18 | J15: ='🤝 B2B'!J18 | ... N15: ='🤝 B2B'!N18 | O15: =SUM(C15:N15)
B16: Vendido Produto (auto) | C16: ='🛠 Produto'!C18 | D16: ='🛠 Produto'!D18 | E16: ='🛠 Produto'!E18 | F16: ='🛠 Produto'!F18 | G16: ='🛠 Produto'!G18 | H16: ='🛠 Produto'!H18 | I16: ='🛠 Produto'!I18 | J16: ='🛠 Produto'!J18 | ... N16: ='🛠 Produto'!N18 | O16: =SUM(C16:N16)
B17: Vendido Licitações (auto) | C17: ='📋 Licitações'!C13 | D17: ='📋 Licitações'!D13 | E17: ='📋 Licitações'!E13 | F17: ='📋 Licitações'!F13 | G17: ='📋 Licitações'!G13 | H17: ='📋 Licitações'!H13 | I17: ='📋 Licitações'!I13 | J17: ='📋 Licitações'!J13 | ... N17: ='📋 Licitações'!N13 | O17: =SUM(C17:N17)
B18: Total Vendido no Mês (auto) | C18: =SUM(C15:C17) | D18: =SUM(D15:D17) | E18: =SUM(E15:E17) | F18: =SUM(F15:F17) | G18: =SUM(G15:G17) | H18: =SUM(H15:H17) | I18: =SUM(I15:I17) | J18: =SUM(J15:J17) | ... N18: =SUM(N15:N17) | O18: =SUM(C18:N18)
B20: DESPESAS
B21: Folha & RH (R$) | O21: =SUM(C21:N21)
B22: Marketing/ADS (R$) | O22: =SUM(C22:N22)
B23: Infra & Tech (R$) | O23: =SUM(C23:N23)
B24: Terceiros & Freelancers (R$) | O24: =SUM(C24:N24)
B25: Outras Despesas (R$) | O25: =SUM(C25:N25)
B26: Despesas Totais (auto) | C26: =SUM(C21:C25) | D26: =SUM(D21:D25) | E26: =SUM(E21:E25) | F26: =SUM(F21:F25) | G26: =SUM(G21:G25) | H26: =SUM(H21:H25) | I26: =SUM(I21:I25) | J26: =SUM(J21:J25) | ... N26: =SUM(N21:N25) | O26: =SUM(C26:N26)
B28: RESULTADO & INDICADORES
B29: Resultado do Mês (auto) | C29: =C12-C26 | D29: =D12-D26 | E29: =E12-E26 | F29: =F12-F26 | G29: =G12-G26 | H29: =H12-H26 | I29: =I12-I26 | J29: =J12-J26 | ... N29: =N12-N26 | O29: =SUM(C29:N29)
B30: Burn Rate (auto) | C30: =IF(C29<0,-C29,0) | D30: =IF(D29<0,-D29,0) | E30: =IF(E29<0,-E29,0) | F30: =IF(F29<0,-F29,0) | G30: =IF(G29<0,-G29,0) | H30: =IF(H29<0,-H29,0) | I30: =IF(I29<0,-I29,0) | J30: =IF(J29<0,-J29,0) | ... N30: =IF(N29<0,-N29,0) | O30: =SUM(C30:N30)
B31: Runway (meses, auto) | C31: =IFERROR(C7/C30,0) | D31: =IFERROR(D7/D30,0) | E31: =IFERROR(E7/E30,0) | F31: =IFERROR(F7/F30,0) | G31: =IFERROR(G7/G30,0) | H31: =IFERROR(H7/H30,0) | I31: =IFERROR(I7/I30,0) | J31: =IFERROR(J7/J30,0) | ... N31: =IFERROR(N7/N30,0) | O31: =IFERROR(AVERAGE(C31:N31),0)
B32: Margem (%, auto) | C32: =IFERROR(C29/C12,0) | D32: =IFERROR(D29/D12,0) | E32: =IFERROR(E29/E12,0) | F32: =IFERROR(F29/F12,0) | G32: =IFERROR(G29/G12,0) | H32: =IFERROR(H29/H12,0) | I32: =IFERROR(I29/I12,0) | J32: =IFERROR(J29/J12,0) | ... N32: =IFERROR(N29/N12,0) | O32: =IFERROR(AVERAGE(C32:N32),0)
B33: Contas a Receber (R$) | O33: =SUM(C33:N33)
B34: Inadimplência (R$) | O34: =SUM(C34:N34)
B36: VENDIDO vs RECEBIDO
B37: Gap Vendido−Recebido (auto) | C37: =C18-C12 | D37: =D18-D12 | E37: =E18-E12 | F37: =F18-F12 | G37: =G18-G12 | H37: =H18-H12 | I37: =I18-I12 | J37: =J18-J12 | ... N37: =N18-N12 | O37: =SUM(C37:N37)
B38: % Conversão Venda→Caixa (auto) | C38: =IFERROR(C12/C18,0) | D38: =IFERROR(D12/D18,0) | E38: =IFERROR(E12/E18,0) | F38: =IFERROR(F12/F18,0) | G38: =IFERROR(G12/G18,0) | H38: =IFERROR(H12/H18,0) | I38: =IFERROR(I12/I18,0) | J38: =IFERROR(J12/J18,0) | ... N38: =IFERROR(N12/N18,0) | O38: =IFERROR(AVERAGE(C38:N38),0)

Sheet 📊 Dashboard
A1: chave | B1: area | C1: label | D1: Jan | E1: Fev | F1: Mar | G1: Abr | H1: Mai | I1: Jun | J1: Jul | K1: Ago | L1: Set | M1: Out | N1: Nov | O1: Dez | P1: Total
A2: saldo_inicial | B2: Financeiro | C2: Saldo Inicial de Caixa | D2: ='💰 Financeiro'!C7 | E2: ='💰 Financeiro'!D7 | F2: ='💰 Financeiro'!E7 | G2: ='💰 Financeiro'!F7 | H2: ='💰 Financeiro'!G7 | I2: ='💰 Financeiro'!H7 | J2: ='💰 Financeiro'!I7 | K2: ='💰 Financeiro'!J7 | ... O2: ='💰 Financeiro'!N7 | P2: =SUM(D2:O2)
A3: receb_b2b | B3: Financeiro | C3: Recebimentos B2B | D3: ='💰 Financeiro'!C8 | E3: ='💰 Financeiro'!D8 | F3: ='💰 Financeiro'!E8 | G3: ='💰 Financeiro'!F8 | H3: ='💰 Financeiro'!G8 | I3: ='💰 Financeiro'!H8 | J3: ='💰 Financeiro'!I8 | K3: ='💰 Financeiro'!J8 | ... O3: ='💰 Financeiro'!N8 | P3: =SUM(D3:O3)
A4: receb_produto | B4: Financeiro | C4: Recebimentos Produto/B2C | D4: ='💰 Financeiro'!C9 | E4: ='💰 Financeiro'!D9 | F4: ='💰 Financeiro'!E9 | G4: ='💰 Financeiro'!F9 | H4: ='💰 Financeiro'!G9 | I4: ='💰 Financeiro'!H9 | J4: ='💰 Financeiro'!I9 | K4: ='💰 Financeiro'!J9 | ... O4: ='💰 Financeiro'!N9 | P4: =SUM(D4:O4)
A5: receb_editais | B5: Financeiro | C5: Recebimentos de Editais | D5: ='💰 Financeiro'!C10 | E5: ='💰 Financeiro'!D10 | F5: ='💰 Financeiro'!E10 | G5: ='💰 Financeiro'!F10 | H5: ='💰 Financeiro'!G10 | I5: ='💰 Financeiro'!H10 | J5: ='💰 Financeiro'!I10 | K5: ='💰 Financeiro'!J10 | ... O5: ='💰 Financeiro'!N10 | P5: =SUM(D5:O5)
A6: receb_outras | B6: Financeiro | C6: Outras Receitas | D6: ='💰 Financeiro'!C11 | E6: ='💰 Financeiro'!D11 | F6: ='💰 Financeiro'!E11 | G6: ='💰 Financeiro'!F11 | H6: ='💰 Financeiro'!G11 | I6: ='💰 Financeiro'!H11 | J6: ='💰 Financeiro'!I11 | K6: ='💰 Financeiro'!J11 | ... O6: ='💰 Financeiro'!N11 | P6: =SUM(D6:O6)
A7: receb_total | B7: Financeiro | C7: Recebimentos Totais | D7: ='💰 Financeiro'!C12 | E7: ='💰 Financeiro'!D12 | F7: ='💰 Financeiro'!E12 | G7: ='💰 Financeiro'!F12 | H7: ='💰 Financeiro'!G12 | I7: ='💰 Financeiro'!H12 | J7: ='💰 Financeiro'!I12 | K7: ='💰 Financeiro'!J12 | ... O7: ='💰 Financeiro'!N12 | P7: =SUM(D7:O7)
A8: vendido_b2b | B8: Financeiro | C8: Vendido B2B | D8: ='💰 Financeiro'!C15 | E8: ='💰 Financeiro'!D15 | F8: ='💰 Financeiro'!E15 | G8: ='💰 Financeiro'!F15 | H8: ='💰 Financeiro'!G15 | I8: ='💰 Financeiro'!H15 | J8: ='💰 Financeiro'!I15 | K8: ='💰 Financeiro'!J15 | ... O8: ='💰 Financeiro'!N15 | P8: =SUM(D8:O8)
A9: vendido_produto | B9: Financeiro | C9: Vendido Produto | D9: ='💰 Financeiro'!C16 | E9: ='💰 Financeiro'!D16 | F9: ='💰 Financeiro'!E16 | G9: ='💰 Financeiro'!F16 | H9: ='💰 Financeiro'!G16 | I9: ='💰 Financeiro'!H16 | J9: ='💰 Financeiro'!I16 | K9: ='💰 Financeiro'!J16 | ... O9: ='💰 Financeiro'!N16 | P9: =SUM(D9:O9)
A10: vendido_licit | B10: Financeiro | C10: Vendido Licitações | D10: ='💰 Financeiro'!C17 | E10: ='💰 Financeiro'!D17 | F10: ='💰 Financeiro'!E17 | G10: ='💰 Financeiro'!F17 | H10: ='💰 Financeiro'!G17 | I10: ='💰 Financeiro'!H17 | J10: ='💰 Financeiro'!I17 | K10: ='💰 Financeiro'!J17 | ... O10: ='💰 Financeiro'!N17 | P10: =SUM(D10:O10)
A11: vendido_total | B11: Financeiro | C11: Total Vendido | D11: ='💰 Financeiro'!C18 | E11: ='💰 Financeiro'!D18 | F11: ='💰 Financeiro'!E18 | G11: ='💰 Financeiro'!F18 | H11: ='💰 Financeiro'!G18 | I11: ='💰 Financeiro'!H18 | J11: ='💰 Financeiro'!I18 | K11: ='💰 Financeiro'!J18 | ... O11: ='💰 Financeiro'!N18 | P11: =SUM(D11:O11)
A12: desp_folha | B12: Financeiro | C12: Folha & RH | D12: ='💰 Financeiro'!C21 | E12: ='💰 Financeiro'!D21 | F12: ='💰 Financeiro'!E21 | G12: ='💰 Financeiro'!F21 | H12: ='💰 Financeiro'!G21 | I12: ='💰 Financeiro'!H21 | J12: ='💰 Financeiro'!I21 | K12: ='💰 Financeiro'!J21 | ... O12: ='💰 Financeiro'!N21 | P12: =SUM(D12:O12)
A13: desp_ads | B13: Financeiro | C13: Marketing/ADS | D13: ='💰 Financeiro'!C22 | E13: ='💰 Financeiro'!D22 | F13: ='💰 Financeiro'!E22 | G13: ='💰 Financeiro'!F22 | H13: ='💰 Financeiro'!G22 | I13: ='💰 Financeiro'!H22 | J13: ='💰 Financeiro'!I22 | K13: ='💰 Financeiro'!J22 | ... O13: ='💰 Financeiro'!N22 | P13: =SUM(D13:O13)
A14: desp_tech | B14: Financeiro | C14: Infra & Tech | D14: ='💰 Financeiro'!C23 | E14: ='💰 Financeiro'!D23 | F14: ='💰 Financeiro'!E23 | G14: ='💰 Financeiro'!F23 | H14: ='💰 Financeiro'!G23 | I14: ='💰 Financeiro'!H23 | J14: ='💰 Financeiro'!I23 | K14: ='💰 Financeiro'!J23 | ... O14: ='💰 Financeiro'!N23 | P14: =SUM(D14:O14)
A15: desp_terceiros | B15: Financeiro | C15: Terceiros & Freelancers | D15: ='💰 Financeiro'!C24 | E15: ='💰 Financeiro'!D24 | F15: ='💰 Financeiro'!E24 | G15: ='💰 Financeiro'!F24 | H15: ='💰 Financeiro'!G24 | I15: ='💰 Financeiro'!H24 | J15: ='💰 Financeiro'!I24 | K15: ='💰 Financeiro'!J24 | ... O15: ='💰 Financeiro'!N24 | P15: =SUM(D15:O15)
A16: desp_outras | B16: Financeiro | C16: Outras Despesas | D16: ='💰 Financeiro'!C25 | E16: ='💰 Financeiro'!D25 | F16: ='💰 Financeiro'!E25 | G16: ='💰 Financeiro'!F25 | H16: ='💰 Financeiro'!G25 | I16: ='💰 Financeiro'!H25 | J16: ='💰 Financeiro'!I25 | K16: ='💰 Financeiro'!J25 | ... O16: ='💰 Financeiro'!N25 | P16: =SUM(D16:O16)
A17: desp_total | B17: Financeiro | C17: Despesas Totais | D17: ='💰 Financeiro'!C26 | E17: ='💰 Financeiro'!D26 | F17: ='💰 Financeiro'!E26 | G17: ='💰 Financeiro'!F26 | H17: ='💰 Financeiro'!G26 | I17: ='💰 Financeiro'!H26 | J17: ='💰 Financeiro'!I26 | K17: ='💰 Financeiro'!J26 | ... O17: ='💰 Financeiro'!N26 | P17: =SUM(D17:O17)
A18: resultado | B18: Financeiro | C18: Resultado do Mês | D18: ='💰 Financeiro'!C29 | E18: ='💰 Financeiro'!D29 | F18: ='💰 Financeiro'!E29 | G18: ='💰 Financeiro'!F29 | H18: ='💰 Financeiro'!G29 | I18: ='💰 Financeiro'!H29 | J18: ='💰 Financeiro'!I29 | K18: ='💰 Financeiro'!J29 | ... O18: ='💰 Financeiro'!N29 | P18: =SUM(D18:O18)
A19: burn | B19: Financeiro | C19: Burn Rate | D19: ='💰 Financeiro'!C30 | E19: ='💰 Financeiro'!D30 | F19: ='💰 Financeiro'!E30 | G19: ='💰 Financeiro'!F30 | H19: ='💰 Financeiro'!G30 | I19: ='💰 Financeiro'!H30 | J19: ='💰 Financeiro'!I30 | K19: ='💰 Financeiro'!J30 | ... O19: ='💰 Financeiro'!N30 | P19: =SUM(D19:O19)
A20: runway | B20: Financeiro | C20: Runway (meses) | D20: ='💰 Financeiro'!C31 | E20: ='💰 Financeiro'!D31 | F20: ='💰 Financeiro'!E31 | G20: ='💰 Financeiro'!F31 | H20: ='💰 Financeiro'!G31 | I20: ='💰 Financeiro'!H31 | J20: ='💰 Financeiro'!I31 | K20: ='💰 Financeiro'!J31 | ... O20: ='💰 Financeiro'!N31 | P20: =IFERROR(AVERAGE(D20:O20),0)
A21: margem | B21: Financeiro | C21: Margem (%) | D21: ='💰 Financeiro'!C32 | E21: ='💰 Financeiro'!D32 | F21: ='💰 Financeiro'!E32 | G21: ='💰 Financeiro'!F32 | H21: ='💰 Financeiro'!G32 | I21: ='💰 Financeiro'!H32 | J21: ='💰 Financeiro'!I32 | K21: ='💰 Financeiro'!J32 | ... O21: ='💰 Financeiro'!N32 | P21: =IFERROR(AVERAGE(D21:O21),0)
A22: contas_receber | B22: Financeiro | C22: Contas a Receber | D22: ='💰 Financeiro'!C33 | E22: ='💰 Financeiro'!D33 | F22: ='💰 Financeiro'!E33 | G22: ='💰 Financeiro'!F33 | H22: ='💰 Financeiro'!G33 | I22: ='💰 Financeiro'!H33 | J22: ='💰 Financeiro'!I33 | K22: ='💰 Financeiro'!J33 | ... O22: ='💰 Financeiro'!N33 | P22: =SUM(D22:O22)
A23: inadimplencia | B23: Financeiro | C23: Inadimplência | D23: ='💰 Financeiro'!C34 | E23: ='💰 Financeiro'!D34 | F23: ='💰 Financeiro'!E34 | G23: ='💰 Financeiro'!F34 | H23: ='💰 Financeiro'!G34 | I23: ='💰 Financeiro'!H34 | J23: ='💰 Financeiro'!I34 | K23: ='💰 Financeiro'!J34 | ... O23: ='💰 Financeiro'!N34 | P23: =SUM(D23:O23)
A24: gap_vendido_receb | B24: Financeiro | C24: Gap Vendido−Recebido | D24: ='💰 Financeiro'!C37 | E24: ='💰 Financeiro'!D37 | F24: ='💰 Financeiro'!E37 | G24: ='💰 Financeiro'!F37 | H24: ='💰 Financeiro'!G37 | I24: ='💰 Financeiro'!H37 | J24: ='💰 Financeiro'!I37 | K24: ='💰 Financeiro'!J37 | ... O24: ='💰 Financeiro'!N37 | P24: =SUM(D24:O24)
A25: conv_caixa | B25: Financeiro | C25: % Conversão Venda→Caixa | D25: ='💰 Financeiro'!C38 | E25: ='💰 Financeiro'!D38 | F25: ='💰 Financeiro'!E38 | G25: ='💰 Financeiro'!F38 | H25: ='💰 Financeiro'!G38 | I25: ='💰 Financeiro'!H38 | J25: ='💰 Financeiro'!I38 | K25: ='💰 Financeiro'!J38 | ... O25: ='💰 Financeiro'!N38 | P25: =IFERROR(AVERAGE(D25:O25),0)
A26: prod_aulas | B26: Produto | C26: Aulas/Hot Seats | D26: ='🛠 Produto'!C7 | E26: ='🛠 Produto'!D7 | F26: ='🛠 Produto'!E7 | G26: ='🛠 Produto'!F7 | H26: ='🛠 Produto'!G7 | I26: ='🛠 Produto'!H7 | J26: ='🛠 Produto'!I7 | K26: ='🛠 Produto'!J7 | ... O26: ='🛠 Produto'!N7 | P26: =SUM(D26:O26)
A27: prod_marcos | B27: Produto | C27: Marcos Entregues | D27: ='🛠 Produto'!C8 | E27: ='🛠 Produto'!D8 | F27: ='🛠 Produto'!E8 | G27: ='🛠 Produto'!F8 | H27: ='🛠 Produto'!G8 | I27: ='🛠 Produto'!H8 | J27: ='🛠 Produto'!I8 | K27: ='🛠 Produto'!J8 | ... O27: ='🛠 Produto'!N8 | P27: =SUM(D27:O27)
A28: prod_sla | B28: Produto | C28: SLA de Entrega | D28: ='🛠 Produto'!C9 | E28: ='🛠 Produto'!D9 | F28: ='🛠 Produto'!E9 | G28: ='🛠 Produto'!F9 | H28: ='🛠 Produto'!G9 | I28: ='🛠 Produto'!H9 | J28: ='🛠 Produto'!I9 | K28: ='🛠 Produto'!J9 | ... O28: ='🛠 Produto'!N9 | P28: =IFERROR(AVERAGE(D28:O28),0)
A29: prod_contratos | B29: Produto | C29: Contratos Ativos | D29: ='🛠 Produto'!C12 | E29: ='🛠 Produto'!D12 | F29: ='🛠 Produto'!E12 | G29: ='🛠 Produto'!F12 | H29: ='🛠 Produto'!G12 | I29: ='🛠 Produto'!H12 | J29: ='🛠 Produto'!I12 | K29: ='🛠 Produto'!J12 | ... O29: ='🛠 Produto'!N12 | P29: =SUM(D29:O29)
A30: prod_nps | B30: Produto | C30: NPS | D30: ='🛠 Produto'!C13 | E30: ='🛠 Produto'!D13 | F30: ='🛠 Produto'!E13 | G30: ='🛠 Produto'!F13 | H30: ='🛠 Produto'!G13 | I30: ='🛠 Produto'!H13 | J30: ='🛠 Produto'!I13 | K30: ='🛠 Produto'!J13 | ... O30: ='🛠 Produto'!N13 | P30: =SUM(D30:O30)
A31: prod_49code_qtd | B31: Produto | C31: Vendas 49 Code (qtd) | D31: ='🛠 Produto'!C16 | E31: ='🛠 Produto'!D16 | F31: ='🛠 Produto'!E16 | G31: ='🛠 Produto'!F16 | H31: ='🛠 Produto'!G16 | I31: ='🛠 Produto'!H16 | J31: ='🛠 Produto'!I16 | K31: ='🛠 Produto'!J16 | ... O31: ='🛠 Produto'!N16 | P31: =SUM(D31:O31)
A32: prod_49code_rec | B32: Produto | C32: Receita 49 Code | D32: ='🛠 Produto'!C17 | E32: ='🛠 Produto'!D17 | F32: ='🛠 Produto'!E17 | G32: ='🛠 Produto'!F17 | H32: ='🛠 Produto'!G17 | I32: ='🛠 Produto'!H17 | J32: ='🛠 Produto'!I17 | K32: ='🛠 Produto'!J17 | ... O32: ='🛠 Produto'!N17 | P32: =SUM(D32:O32)
A33: prod_receita | B33: Produto | C33: Receita Total Produto | D33: ='🛠 Produto'!C18 | E33: ='🛠 Produto'!D18 | F33: ='🛠 Produto'!E18 | G33: ='🛠 Produto'!F18 | H33: ='🛠 Produto'!G18 | I33: ='🛠 Produto'!H18 | J33: ='🛠 Produto'!I18 | K33: ='🛠 Produto'!J18 | ... O33: ='🛠 Produto'!N18 | P33: =SUM(D33:O33)
A34: prod_uptime | B34: Produto | C34: Uptime | D34: ='🛠 Produto'!C21 | E34: ='🛠 Produto'!D21 | F34: ='🛠 Produto'!E21 | G34: ='🛠 Produto'!F21 | H34: ='🛠 Produto'!G21 | I34: ='🛠 Produto'!H21 | J34: ='🛠 Produto'!I21 | K34: ='🛠 Produto'!J21 | ... O34: ='🛠 Produto'!N21 | P34: =IFERROR(AVERAGE(D34:O34),0)
A35: prod_bugs_rep | B35: Produto | C35: Bugs Reportados | D35: ='🛠 Produto'!C22 | E35: ='🛠 Produto'!D22 | F35: ='🛠 Produto'!E22 | G35: ='🛠 Produto'!F22 | H35: ='🛠 Produto'!G22 | I35: ='🛠 Produto'!H22 | J35: ='🛠 Produto'!I22 | K35: ='🛠 Produto'!J22 | ... O35: ='🛠 Produto'!N22 | P35: =SUM(D35:O35)
A36: prod_bugs_res | B36: Produto | C36: Bugs Resolvidos | D36: ='🛠 Produto'!C23 | E36: ='🛠 Produto'!D23 | F36: ='🛠 Produto'!E23 | G36: ='🛠 Produto'!F23 | H36: ='🛠 Produto'!G23 | I36: ='🛠 Produto'!H23 | J36: ='🛠 Produto'!I23 | K36: ='🛠 Produto'!J23 | ... O36: ='🛠 Produto'!N23 | P36: =SUM(D36:O36)
A37: prod_features | B37: Produto | C37: Features Lançadas | D37: ='🛠 Produto'!C24 | E37: ='🛠 Produto'!D24 | F37: ='🛠 Produto'!E24 | G37: ='🛠 Produto'!F24 | H37: ='🛠 Produto'!G24 | I37: ='🛠 Produto'!H24 | J37: ='🛠 Produto'!I24 | K37: ='🛠 Produto'!J24 | ... O37: ='🛠 Produto'!N24 | P37: =SUM(D37:O37)
A38: b2b_ads | B38: B2B | C38: Investimento ADS | D38: ='🤝 B2B'!C7 | E38: ='🤝 B2B'!D7 | F38: ='🤝 B2B'!E7 | G38: ='🤝 B2B'!F7 | H38: ='🤝 B2B'!G7 | I38: ='🤝 B2B'!H7 | J38: ='🤝 B2B'!I7 | K38: ='🤝 B2B'!J7 | ... O38: ='🤝 B2B'!N7 | P38: =SUM(D38:O38)
A39: b2b_leads | B39: B2B | C39: Leads Gerados | D39: ='🤝 B2B'!C8 | E39: ='🤝 B2B'!D8 | F39: ='🤝 B2B'!E8 | G39: ='🤝 B2B'!F8 | H39: ='🤝 B2B'!G8 | I39: ='🤝 B2B'!H8 | J39: ='🤝 B2B'!I8 | K39: ='🤝 B2B'!J8 | ... O39: ='🤝 B2B'!N8 | P39: =SUM(D39:O39)
A40: b2b_mqls | B40: B2B | C40: MQLs | D40: ='🤝 B2B'!C9 | E40: ='🤝 B2B'!D9 | F40: ='🤝 B2B'!E9 | G40: ='🤝 B2B'!F9 | H40: ='🤝 B2B'!G9 | I40: ='🤝 B2B'!H9 | J40: ='🤝 B2B'!I9 | K40: ='🤝 B2B'!J9 | ... O40: ='🤝 B2B'!N9 | P40: =SUM(D40:O40)
...
